Workbook

Sheet Panduan
A1: Mill Smart Log — Test Case Blackbox (RINGKAS)
A2: Pengujian fungsional Web dan Mobile. 170 kasus unik, ± 1.382 jalan, 154 layar tercakup. VERSI RINGKAS — empat kasus komponen bersama dipangkas dari 18× ke 3×; lihat kotak merah di bawah.
A4: Isi berkas ini
A5: Kasus Uji | B5: Satu baris per JALAN — 1.382 baris. Kasus yang berlaku di 18 stasiun sudah dijabarkan menjadi 18 baris, dan nama stasiunnya ada DI DALAM langkahnya. Kolom berlatar kuning diisi penguji.
A6: Rekap | B6: Hitungan otomatis Lulus/Gagal/Tidak diuji per bagian. Terisi sendiri dari Kasus Uji.
A7: Lingkungan & Akun | B7: Yang harus disiapkan sebelum menguji, 6 akun uji, dan matriks peran.
A8: Matriks Stasiun | B8: 18 stasiun beserta keanehan masing-masing yang perlu diperhatikan.
A9: Sudah Diketahui | B9: Dua daftar yang WAJIB dibaca sebelum melapor: catatan yang sudah diketahui tim, dan hal yang terlihat seperti bug tetapi bukan.
A11: Mengapa ada "pola" dan bukan 108 set kasus
A12: Alasannya | B12: Monitor, Form, dan Data Preview (mobile) serta Data Browser, Detail, dan Form (web) berbentuk sama di ke-18 stasiun. Polanya ditulis sekali lalu dijalankan 18×; yang berbeda per stasiun ada di sheet Matriks Stasiun.
A13: Akibatnya | B13: Kolom "Jml Jalan" di sheet Kasus Uji menyebut berapa kali satu kasus dijalankan. 18× berarti sekali per stasiun, 11× sekali per stasiun yang sudah punya laporan.
A15: Tingkat pengujian — baca ini kalau waktunya terbatas
A16: Masalahnya | B16: Daftar penuh 1.382 jalan mencampur dua pertanyaan berbeda: "apakah setiap alur bekerja" dan "apakah ke-18 implementasi stasiun bekerja". Yang pertama butuh 170 jalan; yang kedua butuh sisanya. Kolom Tingkat memisahkannya tanpa membuang apa pun.
A17: Tingkat 1 — ALUR (170 jalan) | B17: Setiap kasus SEKALI, pada stasiun wakil. Menyelesaikan tingkat ini berarti setiap alur sistem sudah pernah dijalankan dan setiap kasus terbukti dapat dieksekusi. Stasiun wakilnya Depricarping (9 kolom bacaan, downtime, temuan, punya master target — paling banyak melewati cabang), Kernel Plant untuk laporan, Business Unit untuk Kelola.
A18: Tingkat 2 — KABEL (88 jalan) | B18: Lima kasus pada 17 stasiun sisanya: MB-FORM-01, MB-PRV-06, WB-FRM-01, WB-BRW-03, WB-DTL-03 (plus LP-W-01 untuk 10 laporan sisanya). Kelimanya yang gagal kalau satu stasiun salah dikabel — jalur tulis, jalur baca, dan penurunan hitungannya.
A19: Tingkat 1+2 = 258 jalan | B19: Ini cakupan yang masuk akal untuk satu putaran manual: 19% dari daftar penuh, sudah melewati setiap alur sekali plus pengabelan setiap stasiun. Saring kolom Tingkat ke 1 dan 2.
A20: Tingkat 3 — SISA (1.124 jalan) | B20: Pengulangan penuh. Untuk putaran rilis, atau ketika satu stasiun berubah — saring Tingkat 3 pada stasiun itu saja.
A21: YANG HILANG, dinyatakan terbuka | B21: Tingkat 1+2 TIDAK membuktikan ke-18 stasiun berperilaku benar pada setiap cabang. Setiap stasiun punya layar dan aturannya sendiri, jadi hasil baik di satu stasiun tidak menjamin stasiun lain — dan temuan yang pernah ada memang hanya muncul di satu stasiun, bukan di semuanya. Melewatkan Tingkat 3 adalah keputusan risiko, bukan penghematan gratis.
A22: Lebih dulu dari memangkas | B22: Pangkas waktu PENYIAPAN, bukan cakupan. Minta tim pengembang menyiapkan satu basis data uji berisi data contoh: dua mill, Production Line dengan stasiun aktif untuk setiap jenis, satu Production Line yang sengaja TIDAK punya stasiun tertentu (prasyarat MB-FORM-15 dan WB-FRM-07), dan satu akun per peran. Menguji di basis data itu membuat banyak langkah "Siapkan…" gugur, dan cakupannya tidak berkurang sedikit pun.
A24: Aturan pengisian kolom Hasil
A25: Lulus | B25: Yang terlihat SAMA dengan Hasil Diharapkan, seluruhnya.
A26: Gagal | B26: Ada perbedaan. Tulis APA YANG TERLIHAT di kolom Catatan, bukan dugaan sebabnya.
A27: Tidak diuji | B27: Prasyaratnya tidak dapat disiapkan. JANGAN ditandai Lulus.
A28: Terhalang | B28: Kasus lain yang gagal membuat kasus ini tidak bisa dijalankan. Sebut ID penghalangnya.
A30: Sebelum menutup satu putaran
A31: Periksa tiga hal | B31: 1) Setiap kasus Prioritas Tinggi punya Hasil, bukan sel kosong. 2) Setiap baris Gagal punya No. Bug. 3) Setiap baris Tidak diuji menyebut prasyarat mana yang tak bisa disiapkan.
A33: VERSI RINGKAS — BACA SEBELUM MEMAKAI | B33: Empat kasus dipangkas dari 18x menjadi 3x, menghemat 60 jalan (1.509 menjadi 1.449): - MB-PRV-02, MB-PRV-04, MB-PRV-08 menguji panel filter - MB-PRV-07 menguji panel verifikasi Ketiganya memeriksa panel filter dan panel verifikasi yang SAMA di ke-18 layar Data Preview — satu tampilan yang dipakai bersama, jadi perilakunya tidak dapat berbeda per stasiun. Dijalankan pada tiga stasiun berbeda bentuk (Depricarping 24-slot, Weighbridge per-transaksi, Effluent Plant berkolom status). RISIKONYA, dinyatakan terbuka: kalau kelak salah satu layar Data Preview berhenti memakai komponen itu dan menulis filternya sendiri, pemangkasan ini tidak akan menangkapnya. Versi PENUH tetap ada di berkas tanpa akhiran "-Ringkas" — pakai itu untuk putaran rilis. TIDAK dipangkas meski juga 18x: breadcrumb (MB-MON-06) ditulis ulang di setiap view, bukan komponen bersama; dan ke-18 stasiun punya service, Form, serta Data Preview-nya sendiri-sendiri — bug di satu stasiun tidak mengatakan apa pun tentang yang lain.
A35: Kasus yang prasyaratnya tidak tersedia BUKAN kasus yang lulus. Menandainya Lulus membuat laporan pengujian menyatakan sesuatu yang tidak pernah diperiksa — dan itu lebih berbahaya daripada kolom yang dibiarkan kosong.

Sheet Kasus Uji
A1: Kasus Uji — setiap jalan dijabarkan satu baris (RINGKAS)
A2: Kasus yang berlaku di 18 stasiun dijabarkan menjadi 18 baris, masing-masing menyebut stasiunnya DI DALAM langkahnya — tidak ada lagi "18×" yang harus diterjemahkan sendiri. Kolom berlatar kuning diisi penguji.
A4: No | B4: Tingkat | C4: ID Jalan | D4: ID Kasus | E4: Stasiun / Varian | F4: Bagian | G4: Judul | H4: Peran | I4: Prasyarat | J4: Langkah | K4: Hasil Diharapkan | L4: Prioritas | M4: Catatan QA | N4: Tanggal | O4: Penguji | P4: Hasil | Q4: No. Bug | R4: Catatan / apa yang terlihat
A5: 1 | B5: 1 | C5: LS-01 | D5: LS-01 | E5: — | F5: Aturan lintas-sistem (LS-) | G5: Peran yang tidak berhak ditolak dengan halaman 403, bukan halaman kosong | H5: semua, bergantian | I5: matriks peran bagian 1.3 dibaca lebih dulu | J5: 1. Login di web (buka /login, isi username dan password akun pada kolom Peran, tekan Login) sebagai salah satu peran. 2. Buka matriks peran bagian 1.3. Pilih satu baris yang bertanda "—" untuk peran itu. 3. Ketik alamat layar itu langsung di bilah alamat browser (lihat tabel bagian 0.3) — jangan lewat menu, karena menunya memang tidak akan muncul. 4. Tekan Enter. 5. Ulangi langkah 2–4 untuk setiap baris bertanda "—" pada peran itu. 6. Ulangi seluruh kasus untuk keempat peran. | K5: - Muncul halaman 403 / Akses Ditolak berbahasa Indonesia. - Halaman 403 itu masih berada di dalam kerangka aplikasi — sidebar dan tombol Logout masih ada. - BUKAN halaman putih, BUKAN pesan galat teknis (stack trace, "Server Error", kode dalam bahasa Inggris). - BUKAN dialihkan diam-diam ke beranda: alamat di bilah alamat tetap alamat yang diketik. | L5: Tinggi
A6: 2 | B6: 1 | C6: LS-02 | D6: LS-02 | E6: — | F6: Aturan lintas-sistem (LS-) | G6: Menu yang tidak boleh diakses juga tidak muncul di sidebar | H6: semua, bergantian | I6: — | J6: 1. Login di web (buka /login, isi username dan password akun pada kolom Peran, tekan Login) sebagai salah satu peran. 2. Baca seluruh isi sidebar dari atas ke bawah, catat setiap menu yang terlihat. 3. Bandingkan catatan itu dengan kolom peran tersebut pada matriks bagian 1.3. 4. Klik setiap menu yang terlihat, satu per satu. 5. Ulangi untuk keempat peran. | K6: - Sidebar hanya memuat menu yang bertanda ✓ untuk peran itu di matriks 1.3. - Tidak ada menu yang bertanda "—" tetapi tetap terlihat. - Setiap menu yang diklik terbuka — tidak ada satu pun yang menjawab 403. Menu yang terlihat tapi menolak saat diklik adalah bug. | L6: Tinggi
A7: 3 | B7: 1 | C7: LS-03 | D7: LS-03 | E7: — | F7: Aturan lintas-sistem (LS-) | G7: Data mill lain tidak pernah terlihat | H7: SPV-A, lalu SPV-B | I7: Mill A dan Mill B keduanya punya record pada tanggal yang sama | J7: 1. Login di web (buka /login, isi username dan password akun pada kolom Peran, tekan Login) sebagai SPV-A. 2. Login di web, lalu sidebar > Data > <Stasiun> (/data/<stasiun>) untuk satu stasiun. Catat jumlah data yang tertulis dan seluruh nama Production Line yang muncul di pemilih maupun di tabel. 3. Buka pemilih Production Line dan catat seluruh pilihannya. 4. Logout. 5. Login di web (buka /login, isi username dan password akun pada kolom Peran, tekan Login) sebagai SPV-B, lalu buka layar yang sama. 6. Bandingkan dengan catatan langkah 2 dan 3. | K7: - SPV-B tidak melihat satu pun record milik Mill A. - SPV-B tidak melihat satu pun nama Production Line Mill A — tidak di pemilih, tidak di tabel, tidak di keterangan mana pun. - Jumlah datanya berbeda, dan yang terlihat hanya milik Mill B. | L7: Tinggi
A8: 4 | B8: 1 | C8: LS-04 | D8: LS-04 | E8: — | F8: Aturan lintas-sistem (LS-) | G8: Akun tanpa mill ditolak dengan pesan yang menyebut sebabnya | H8: NOMILL | I8: akun Supervisor yang kolom mill-nya kosong | J8: 1. Buka /login. Isi username dan password NOMILL (akun Supervisor yang kolom mill-nya kosong), tekan Login. 2. Baca pesan yang muncul kata per kata. 3. Bila ternyata berhasil masuk, lanjutkan: Login di web, lalu sidebar > Data > <Stasiun> (/data/<stasiun>) satu stasiun, Login di web, sidebar > Laporan Stasiun (/reports), tekan tile <Stasiun> (/reports/<stasiun>), lalu pilih Periode dan Production Line satu stasiun, lalu Login di web, lalu sidebar > Dashboard (/dashboard). Baca isi ketiga layar. | K8: - Akun itu ditolak, bukan dibiarkan masuk lalu melihat layar kosong. Boleh ditolak di Login (tidak pernah sampai ke layar mana pun), boleh juga masuk lalu setiap layar menampilkan pesannya — keduanya sama-sama benar, selama penolakannya disebutkan sebabnya. - Pesannya menyebut mill — misalnya "Akun Anda belum terhubung ke mill" — atau kalimat sepadan yang menyebut mill. - Pesannya mengarahkan tindakan (mis. menghubungi Admin), bukan sekadar menyatakan ada yang tidak sesuai. - Pesannya tidak menyebut pilihan yang tidak pernah dibuat pengguna. Layar Login hanya meminta username dan password; pesan yang menyebut sesuatu "yang dipilih" mengirim pengguna mencari pilihan yang tidak ada. - BUKAN tabel kosong. BUKAN angka nol. BUKAN daftar seluruh mill. BUKAN pesan periksa koneksi. | L8: Tinggi | M8: tabel kosong di sini adalah bug, bukan hasil yang benar. Tabel kosong terbaca "mill ini tidak punya data", padahal yang benar "akun Anda belum diatur". Hal yang sama berlaku untuk pesan yang benar menolak tetapi salah menyebut sebabnya.
A9: 5 | B9: 1 | C9: LS-05 | D9: LS-05 | E9: — | F9: Aturan lintas-sistem (LS-) | G9: Hanya Admin melihat pemilih Mill | H9: SPV-A, MGR-A, ADM | I9: minimal 2 mill ada | J9: 1. Login di web, sidebar > Laporan Stasiun (/reports), tekan tile <Stasiun> (/reports/<stasiun>), lalu pilih Periode dan Production Line untuk satu stasiun sebagai SPV-A. Cari pemilih Mill di panel filter. 2. Logout. Ulangi sebagai MGR-A. 3. Logout. Ulangi sebagai ADM. | K9: - SPV-A: tidak ada pemilih Mill. Nama mill-nya hanya ditampilkan sebagai teks. - MGR-A: sama — hanya ditampilkan, tidak dapat diubah. - ADM: ada pemilih Mill, dan isinya memuat kedua mill. | L9: Tinggi
A10: 6 | B10: 1 | C10: LS-06 | D10: LS-06 | E10: — | F10: Aturan lintas-sistem (LS-) | G10: Sesi berakhir mengarahkan ke Login tanpa pesan jaringan | H10: semua | I10: sudah login; sesi/token dibuat kedaluwarsa (mis. akun dinonaktifkan Admin dari layar lain) | J10: 1. Login di web (buka /login, isi username dan password akun pada kolom Peran, tekan Login) sebagai SPV-A. Biarkan layar terbuka. 2. Di jendela browser lain, Login di web, lalu sidebar > Kelola User & Role (/users) sebagai ADM dan nonaktifkan akun SPV-A. 3. Kembali ke jendela SPV-A. Lakukan satu tindakan apa pun: muat ulang halaman, ubah satu filter, atau tekan Simpan. 4. Baca pesan yang muncul. | K10: - Diarahkan ke layar Login. - Pesannya menyebut sesi/akun — mis. sesi berakhir atau akun dinonaktifkan. - Pesannya tidak menyuruh memeriksa koneksi atau jaringan. Kalau muncul "Periksa koneksi Anda", itu bug. | L10: Tinggi | M10: "Periksa koneksi Anda" pada sesi yang berakhir mengirim pengguna memeriksa sinyal — arah yang salah. Kalau pesan itu muncul, ini bug.
A11: 7 | B11: 1 | C11: LS-07 | D11: LS-07 | E11: — | F11: Aturan lintas-sistem (LS-) | G11: Nol dirender sebagai pernyataan, bukan sebagai angka 0 | H11: SPV-A | I11: satu stasiun / satu periode yang belum ada datanya sama sekali | J11: 1. Siapkan satu stasiun atau satu periode yang belum ada datanya sama sekali. 2. Login di web, lalu sidebar > Dashboard (/dashboard) sebagai SPV-A. Baca setiap angka di layar. 3. Login di web, sidebar > Laporan Stasiun (/reports), tekan tile <Stasiun> (/reports/<stasiun>), lalu pilih Periode dan Production Line untuk stasiun/periode kosong itu. Baca setiap angka dan setiap kartu. 4. Login di web, lalu sidebar > Production Process Activity (/production-process-activity). Baca tile stasiun yang belum ada datanya. | K11: - Tempat yang belum ada datanya berbunyi "belum ada input", "tidak tersedia", atau tanda pisah "—". - BUKAN angka 0. BUKAN 0%. BUKAN 0,0. - Angka 0 hanya muncul bila memang sudah diukur dan hasilnya nol — bukan untuk menyatakan ketiadaan data. | L11: Sedang | M11: angka 0 menyatakan "sudah diukur, hasilnya nol". Belum ada data adalah hal berbeda, dan keduanya tidak boleh terlihat sama.
A12: 8 | B12: 1 | C12: LS-08 | D12: LS-08 | E12: — | F12: Aturan lintas-sistem (LS-) | G12: Production Line wajib dipilih di Laporan Periode, termasuk saat hanya ada satu line | H12: SPV-A | I12: satu mill dengan satu Production Line, dan satu mill dengan dua line | J12: 1. Siapkan satu mill dengan satu Production Line, dan satu mill dengan dua line. 2. Login di web (buka /login, isi username dan password akun pada kolom Peran, tekan Login) sebagai ADM, lalu sidebar → Laporan Stasiun → tekan tile satu stasiun. 3. Pilih mill yang hanya punya satu line. Jangan pilih Production Line apa pun. Baca layar. 4. Pilih Production Line satu-satunya itu. Baca layar. 5. Ganti ke mill yang punya dua line. Baca layar. | K12: - Pada langkah 3, meski hanya ada satu pilihan, line itu tidak terpilih otomatis: layar meminta memilih Production Line dan tidak menampilkan satu angka pun. - Pada langkah 4, angka-angkanya muncul. - Pada langkah 5, pilihan line direset — angkanya hilang lagi sampai line dipilih. | L12: Tinggi | M12: memilih sendiri line tunggal akan membuat pembaca mengira ia melihat seluruh mill, padahal ia melihat satu line yang kebetulan satu-satunya hari itu.
A13: 9 | B13: 1 | C13: LS-09 | D13: LS-09 | E13: — | F13: Aturan lintas-sistem (LS-) | G13: Mengirim id Production Line milik mill lain diabaikan, bukan ditolak dengan galat | H13: SPV-A | I13: id line Mill B diketahui (ambil dari sesi SPV-B) | J13: 1. Login di web, sidebar > Laporan Stasiun (/reports), tekan tile <Stasiun> (/reports/<stasiun>), lalu pilih Periode dan Production Line untuk satu stasiun sebagai SPV-A, pilih periode dan line milik Mill A. Catat angkanya. 2. Salin alamat dari bilah alamat. Di dalamnya ada bagian production_line_id=<id>. 3. Ambil id Production Line milik Mill B (dari Login di web, lalu sidebar > Kelola <Tingkat> (/master-data/<tingkat>) → Kelola Production Line sebagai ADM). 4. Tempel alamat langkah 2 dengan production_line_id diganti id Mill B itu, lalu tekan Enter. | K13: - Halaman tetap terbuka — bukan 403, bukan galat. - Line mill lain itu diabaikan: layar jatuh ke keadaan "belum memilih Production Line", atau pemilihnya kembali kosong. - Nama Production Line Mill B tidak pernah tercetak di layar — tidak di pemilih, tidak di judul, tidak di keterangan. Idnya boleh tergaung di alamat (pemanggil sendiri yang mengirimnya); namanya tidak boleh. | L13: Tinggi
A14: 10 | B14: 1 | C14: LS-10 | D14: LS-10 | E14: — | F14: Aturan lintas-sistem (LS-) | G14: Periode tertutup mengunci input, periode draft/terbuka tidak | H14: SPV-A (input), ADM (ubah status) | I14: satu periode yang mencakup hari ini | J14: 1. Login di web, lalu sidebar > Kelola Periode Pelaporan (/master-data/periods) sebagai ADM. Pilih satu periode yang stasiunnya masih Terbuka. 2. Login di mobile, buka Monitor <Stasiun>, lalu tekan New Data (/stations/<stasiun>/form/<id>) sebagai OPR-A untuk stasiun itu. Isi satu baris, tekan Simpan. Catat hasilnya. 3. Kembali ke Login di web, lalu sidebar > Kelola Periode Pelaporan (/master-data/periods) sebagai ADM. Pada periode itu, tekan Tutup untuk stasiun tersebut. 4. Ulangi langkah 2: coba simpan satu record baru untuk stasiun yang sama pada tanggal dalam periode itu. 5. Kembali sebagai ADM, tekan Buka Kembali pada stasiun itu. 6. Ulangi langkah 2 sekali lagi. | K14: - Langkah 2 (Terbuka): tersimpan. - Langkah 4 (Tertutup): ditolak, dengan pesan yang menyebut periode tertutup. Record tidak tersimpan. - Langkah 6 (Terbuka kembali): tersimpan lagi. - Periode berstatus draft berperilaku sama seperti terbuka — tidak mengunci. | L14: Tinggi
A15: 11 | B15: 1 | C15: LS-11 | D15: LS-11 | E15: — | F15: Aturan lintas-sistem (LS-) | G15: Ekspor menghasilkan berkas yang benar-benar terbuka | H15: SPV-A | I15: ada data pada filter yang dipilih | J15: 1. Login di web, sidebar > Laporan Stasiun (/reports), tekan tile <Stasiun> (/reports/<stasiun>), lalu pilih Periode dan Production Line untuk satu stasiun, pilih periode dan line yang punya data. 2. Tekan Ekspor CSV. Tunggu berkas terunduh. 3. Buka berkas itu dengan Excel atau LibreOffice. 4. Tekan Ekspor Excel. Tunggu berkas terunduh, lalu buka. 5. Bandingkan beberapa angka di berkas dengan angka di layar. | K15: - Kedua berkas benar-benar terunduh dan punya nama berkas yang menyebut stasiun dan periode. - Keduanya terbuka tanpa peringatan rusak di Excel/LibreOffice. - Baris pertama adalah baris judul kolom yang terbaca, bukan kode teknis. - Angka yang dicocokkan sama dengan yang di layar. - Huruf berakhiran Indonesia (mis. nama dengan é atau karakter khusus) tidak berubah menjadi simbol aneh. | L15: Tinggi
A16: 12 | B16: 1 | C16: LS-12 | D16: LS-12 | E16: — | F16: Aturan lintas-sistem (LS-) | G16: Ekspor di mobile hanya CSV | H16: OPR-A | I16: — | J16: 1. Login di mobile, Dashboard & Reporting > Reporting, tekan tile <Stasiun> (/reports/<stasiun>), lalu pilih Periode dan Production Line untuk satu stasiun, pilih periode dan line yang punya data. 2. Baca seluruh tombol di bagian bawah layar. 3. Tekan tombol ekspor yang ada. | K16: - Hanya ada satu pilihan ekspor, dan itu CSV. - Tidak ada tombol Ekspor Excel di mobile. - Berkasnya terunduh dan dapat dibuka. | L16: Sedang
A17: 13 | B17: 1 | C17: LS-13 | D17: LS-13 | E17: — | F17: Aturan lintas-sistem (LS-) | G17: Seluruh tampilan berbahasa Indonesia | H17: semua | I17: — | J17: 1. Jalankan satu kasus apa pun sampai selesai pada layar yang diuji. 2. Baca seluruh teks di layar: judul, label kolom, tombol, keterangan, dan pesan galat. 3. Picu sengaja satu galat (mis. kosongkan kolom wajib lalu Simpan) dan baca pesannya. | K17: - Seluruh teks berbahasa Indonesia. - Pesan galat juga berbahasa Indonesia — bukan "The field is required", bukan "Unauthenticated". - Nama kolom teknis (mis. production_line_id) tidak muncul di pesan yang dibaca pengguna. - Istilah stasiun dan satuan boleh tetap berbahasa Inggris bila itu memang istilah pabrik (mis. "Ripple Mill", "mmH2O"). | L17: Sedang
A18: 14 | B18: 1 | C18: LS-14 | D18: LS-14 | E18: — | F18: Aturan lintas-sistem (LS-) | G18: Tidak ada kolom input yang mati tanpa alasan | H18: SPV-A, MGR-A | I18: — | J18: 1. Login di web, buka /data/<stasiun> (<Stasiun>), lalu tekan Tambah (/data/<stasiun>/create) untuk satu stasiun. 2. Coba klik dan mengetik pada setiap kolom input di layar, satu per satu. 3. Catat kolom mana pun yang tidak dapat diketik atau tampak kelabu. 4. Untuk setiap kolom seperti itu, cari keterangan di layar yang menjelaskan sebabnya. | K18: - Tidak ada kolom input yang mati tanpa alasan yang tertulis di layar. - Kolom yang memang tidak boleh diubah (mis. Tanggal yang terisi otomatis) punya keterangan yang menyebutkan itu. - Kolom Checked By / Acknowledged By yang tidak dapat diisi peran itu disertai keterangan siapa yang boleh mengisinya. | L18: Sedang
A19: 15 | B19: 1 | C19: LS-15 | D19: LS-15 | E19: — | F19: Aturan lintas-sistem (LS-) | G19: Kolom tanggal dan jam bisa diketik manual, bukan hanya lewat pemilih | H19: SPV-A | I19: — | J19: 1. Login di web, buka /data/<stasiun> (<Stasiun>), lalu tekan Tambah (/data/<stasiun>/create) untuk satu stasiun yang punya kolom tanggal atau jam. 2. Klik kolom tanggal, lalu ketik tanggalnya langsung dari papan tulis (mis. 08/10/2026). 3. Hapus isinya, lalu pilih tanggal yang sama lewat ikon kalender. 4. Ulangi langkah 2 dan 3 untuk kolom jam, bila ada. | K19: - Kolom tanggal dapat diketik manual dan nilainya diterima. - Kolom tanggal juga dapat diisi lewat pemilih kalender. - Keduanya menghasilkan nilai yang sama — tidak ada yang hanya menerima salah satu cara. - Hal yang sama berlaku untuk kolom jam. | L19: Sedang
A20: 16 | B20: 1 | C20: LS-16 | D20: LS-16 | E20: — | F20: Aturan lintas-sistem (LS-) | G20: Laporan tidak menandai satu nilai pun sebagai "di luar batas" | H20: SPV-A | I20: ada record dengan nilai yang jelas-jelas jauh di luar target (mis. suhu 3× batas) | J20: 1. Login di web, sidebar > Laporan Stasiun (/reports), tekan tile <Stasiun> (/reports/<stasiun>), lalu pilih Periode dan Production Line untuk satu stasiun yang punya master target (Depricarping, Grading, Kernel Plant, Pressing, atau Threshing). 2. Pilih periode dan line yang punya data. 3. Bandingkan tiap angka rata-rata dengan kolom target di sebelahnya. Cari minimal satu angka yang jelas di luar rentang targetnya. 4. Perhatikan angka itu: apakah ia diberi warna, tebal, ikon peringatan, atau latar berbeda? 5. Cari kotak keterangan di layar yang menjelaskan ketiadaan penandaan itu. | K20: - Angka yang di luar batas tidak ditandai apa pun: tidak merah, tidak kuning, tidak ada ikon, tidak ada badge. - Ada kotak keterangan "Mengapa Tidak Ada Nilai yang Ditandai" yang menjelaskan sebabnya. - Keterangan itu menyebut tiga alasan, bukan satu. - Cara memeriksa yang salah: jangan mencari kata "di luar batas" di halaman — kalimat penjelasnya sendiri memuat frasa itu. Yang diperiksa adalah tampilan angkanya. | L20: Sedang | M20: ketiadaan penandaan di sini disengaja, bukan fitur yang belum selesai. Yang harus dilaporkan sebagai bug adalah kalau penandaan itu muncul, atau kalau kalimat penjelasnya hilang.
A21: 17 | B21: 1 | C21: AU-01 | D21: AU-01 | E21: — | F21: Autentikasi & Akun (AU-) | G21: Login berhasil mengarahkan ke beranda yang sesuai perannya | H21: OPR-A, SPV-A, MGR-A, ADM | I21: keempat akun aktif | J21: 1. Buka /login. Isi username dan password OPR-A, tekan Login. 2. Catat alamat yang dituju dan seluruh isi sidebar. 3. Logout. Ulangi langkah 1–2 untuk SPV-A. 4. Logout. Ulangi untuk MGR-A. 5. Logout. Ulangi untuk ADM. | K21: - Keempatnya berhasil masuk. - OPR-A mendarat di Beranda Operator (/beranda) dengan pesan bahwa akses webnya terbatas; sidebar hanya memuat Beranda dan Ganti Password. - SPV-A, MGR-A, ADM mendarat di beranda masing-masing dengan menu lengkap sesuai matriks 1.3. - Tidak satu pun mendarat di halaman kosong atau halaman galat. | L21: Tinggi
A22: 18 | B22: 1 | C22: AU-02 | D22: AU-02 | E22: — | F22: Autentikasi & Akun (AU-) | G22: Login gagal: password salah | H22: SPV-A | I22: — | J22: 1. Buka /login. 2. Isi username SPV-A yang benar, dan password yang salah. 3. Tekan Login. 4. Catat bunyi pesannya kata per kata — akan dibandingkan di AU-03. | K22: - Tetap di layar Login; tidak masuk. - Muncul pesan galat berbahasa Indonesia. - Pesannya tidak menyebutkan apakah username-nya terdaftar atau tidak (mis. bukan "Password salah" yang memastikan usernamenya ada). | L22: Tinggi
A23: 19 | B23: 1 | C23: AU-03 | D23: AU-03 | E23: — | F23: Autentikasi & Akun (AU-) | G23: Login gagal: username tidak ada | H23: — | I23: — | J23: 1. Buka /login. 2. Isi username yang tidak terdaftar (mis. tidakada999), dan password apa saja. 3. Tekan Login. 4. Bandingkan bunyi pesannya dengan catatan AU-02 langkah 4. | K23: - Tetap di layar Login; tidak masuk. - Pesannya sama bunyinya kata per kata dengan AU-02. - Kalau bunyinya berbeda, itu bug: perbedaan bunyi memberi tahu orang luar username mana yang terdaftar. | L23: Tinggi
A24: 20 | B24: 1 | C24: AU-04 | D24: AU-04 | E24: — | F24: Autentikasi & Akun (AU-) | G24: Akun yang dinonaktifkan tidak bisa masuk, dan yang sedang masuk dikeluarkan | H24: ADM + SPV-A | I24: SPV-A sedang login di satu browser | J24: 1. Login di web (buka /login, isi username dan password akun pada kolom Peran, tekan Login) sebagai SPV-A di satu browser. Biarkan terbuka di layar Data Browser salah satu stasiun. 2. Di browser kedua, Login di web, lalu sidebar > Kelola User & Role (/users) sebagai ADM. 3. Cari akun SPV-A, tekan Nonaktifkan, setujui konfirmasinya. 4. Kembali ke browser pertama. Muat ulang halaman atau ubah satu filter. 5. Logout dari browser pertama bila belum. Coba Login di web (buka /login, isi username dan password akun pada kolom Peran, tekan Login) lagi sebagai SPV-A. 6. Sebagai ADM, aktifkan kembali akun SPV-A supaya kasus lain tidak terhalang. | K24: - Langkah 4: SPV-A dikeluarkan ke layar Login — sesi yang sedang berjalan tidak dibiarkan hidup. - Langkah 5: login gagal, dengan pesan bahwa akunnya tidak aktif. - Pesannya tidak menyuruh memeriksa koneksi. | L24: Tinggi
A25: 21 | B25: 1 | C25: AU-05 | D25: AU-05 | E25: — | F25: Autentikasi & Akun (AU-) | G25: Login Mobile berhasil untuk keempat peran | H25: OPR-A, SPV-A, MGR-A, ADM | I25: — | J25: 1. Buka aplikasi mobile. Isi username dan password OPR-A, tekan Login. 2. Catat layar yang dituju dan isinya. 3. Logout. Ulangi untuk SPV-A. 4. Logout. Ulangi untuk MGR-A. 5. Logout. Ulangi untuk ADM. | K25: - Keempatnya berhasil masuk — termasuk ADM, meski mobile bukan alur yang dirancang untuknya. - OPR-A dan SPV-A mendarat di Home dengan daftar stasiun. - MGR-A juga masuk dan melihat Home. - Tidak ada yang berhenti di layar kosong atau layar memuat yang tidak selesai. | L25: Tinggi
A26: 22 | B26: 1 | C26: AU-06 | D26: AU-06 | E26: — | F26: Autentikasi & Akun (AU-) | G26: Tamu diarahkan ke Login, tidak melihat isi apa pun | H26: belum login | I26: — | J26: 1. Pastikan tidak sedang login (buka jendela privat/incognito, atau logout lebih dulu). 2. Ketik /dashboard di bilah alamat, tekan Enter. 3. Perhatikan layar selama perpindahan — apakah ada isi yang sempat berkedip terlihat? 4. Ulangi untuk /data/weighbridge, /reports, /master-data/periods, dan /users. | K26: - Setiap alamat diarahkan ke Login. - Tidak ada isi halaman yang sempat terlihat, bahkan sekejap — tidak ada angka, tidak ada nama, tidak ada kerangka tabel. - Alamat akhir di bilah alamat adalah /login. | L26: Tinggi
A27: 23 | B27: 1 | C27: AU-07 | D27: AU-07 | E27: — | F27: Autentikasi & Akun (AU-) | G27: Ganti Password berhasil, dan password lama berhenti berlaku | H27: SPV-A (web), OPR-A (mobile) | I27: — | J27: 1. Login di web, lalu sidebar > Ganti Password (/settings/password) sebagai SPV-A. 2. Isi password lama dengan benar, isi password baru dua kali, tekan Simpan. 3. Logout. 4. Coba login dengan password baru. 5. Logout. Coba login dengan password lama. 6. Kembalikan password ke nilai semula supaya kasus lain tidak terhalang. | K27: - Langkah 2 berhasil, dengan pesan konfirmasi. - Langkah 4 berhasil masuk. - Langkah 5 gagal — password lama berhenti berlaku. | L27: Tinggi
A28: 24 | B28: 1 | C28: AU-08 | D28: AU-08 | E28: — | F28: Autentikasi & Akun (AU-) | G28: Ganti Password ditolak bila password lama salah | H28: SPV-A | I28: — | J28: 1. Login di web, lalu sidebar > Ganti Password (/settings/password) sebagai SPV-A. 2. Isi password lama dengan nilai yang salah, isi password baru dua kali, tekan Simpan. 3. Baca letak pesan galatnya. 4. Logout, lalu login dengan password yang sebenarnya masih berlaku. | K28: - Ditolak, dengan pesan galat yang muncul di sebelah kolom password lama — bukan sebagai satu pesan umum di atas form. - Langkah 4 berhasil: password tidak berubah sama sekali. | L28: Tinggi
A29: 25 | B29: 1 | C29: AU-09 | D29: AU-09 | E29: — | F29: Autentikasi & Akun (AU-) | G29: Logout mencabut sesi perangkat itu | H29: OPR-A | I29: — | J29: 1. Login di web, lalu sidebar > Data > <Stasiun> (/data/<stasiun>) sebagai SPV-A untuk satu stasiun. Catat satu angka atau nama yang terlihat. 2. Tekan Logout. 3. Tekan tombol Back browser satu kali. 4. Ketik ulang alamat Data Browser stasiun itu. | K29: - Langkah 2 mengarahkan ke Login. - Langkah 3: isi halaman lama tidak terlihat lagi — tidak ada data yang masih terbaca dari cache browser. - Langkah 4 juga diarahkan ke Login. | L29: Tinggi
A30: 26 | B30: 1 | C30: MB-HOME-01 | D30: MB-HOME-01 | E30: — | F30: Mobile — Operasional Stasiun (MB-) | G30: Home menampilkan stasiun yang ditugaskan | H30: OPR-A | I30: — | J30: 1. Login di mobile (buka aplikasi, isi username dan password, tekan Login), mendarat di /home sebagai OPR-A. 2. Baca seluruh isi layar Home: salam, nama mill, dan daftar/tautan stasiun. 3. Hitung berapa stasiun yang terlihat. | K30: - Nama pengguna dan nama mill-nya tercetak. - Ada jalan menuju Station List yang terlihat jelas. - Tidak ada stasiun milik mill lain yang terlihat. - Tidak ada bagian yang kosong tanpa keterangan. | L30: Tinggi
A31: 27 | B31: 1 | C31: MB-HOME-02 | D31: MB-HOME-02 | E31: — | F31: Mobile — Operasional Stasiun (MB-) | G31: Station List mengantar ke Monitor stasiun yang benar | H31: OPR-A | I31: — | J31: 1. Login di mobile, tekan Station List (/stations); pilih Production Line bila diminta sebagai OPR-A. 2. Catat urutan dan nama ke-18 tile stasiun. 3. Tekan tile Pressing. 4. Baca judul layar yang terbuka dan alamatnya. 5. Tekan Back, lalu ulangi langkah 3–4 untuk Kernel Plant dan Weighbridge. | K31: - Ke-18 tile tampil. - Setiap tile mendarat di Monitor stasiun yang sama dengan namanya — judulnya cocok, alamatnya /stations/<stasiun>/monitor. - Tidak ada tile yang mendarat di stasiun lain. | L31: Tinggi
A32: 28 | B32: 1 | C32: MB-HOME-03 | D32: MB-HOME-03 | E32: — | F32: Mobile — Operasional Stasiun (MB-) | G32: Pilihan Production Line diingat perangkat dan dibagi antar layar | H32: OPR-A | I32: mill punya 2 line | J32: 1. Pastikan mill OPR-A punya 2 Production Line. 2. Login di mobile, tekan Station List (/stations); pilih Production Line bila diminta sebagai OPR-A. Pilih Line 1 pada pemilih Production Line. 3. Masuk ke Monitor satu stasiun. Catat Production Line yang tertulis. 4. Tekan Back ke Station List. Perhatikan pemilihnya. 5. Tutup aplikasi sepenuhnya, lalu buka lagi dan login ulang. 6. Buka Station List. Perhatikan pemilihnya. 7. Ganti ke Line 2, lalu buka Monitor stasiun yang sama. | K32: - Langkah 4: pemilih masih menunjukkan Line 1 — pilihannya tidak lupa saat berpindah layar. - Langkah 6: masih Line 1 — pilihannya diingat perangkat setelah aplikasi ditutup. - Langkah 7: Monitor kini menunjukkan Line 2, dan daftar draftnya ikut berubah sesuai line itu. | L32: Sedang
... A87: 83 | B87: 3 | C87: MB-MON-03 / Process Quality Control | D87: MB-MON-03 | E87: Process Quality Control | F87: Mobile — Operasional Stasiun (MB-) | G87: New Data membuat header saja, grid masih kosong | H87: OPR-A | I87: — | J87: 1. Login di mobile, Station List, lalu tekan tile Process Quality Control (/stations/process-quality-control/monitor). 2. Tekan New Data. 3. Baca bagian header: kolom identitas dan Tanggal. 4. Baca bagian grid di bawahnya: berapa baris yang sudah ada? | K87: - Layar Form terbuka. - Kolom Tanggal sudah terisi otomatis dengan tanggal hari ini. - Kolom identitas unit kosong dan dapat diketik. - Grid slot waktu masih kosong — belum ada satu baris pun. (Untuk stasiun per-transaksi, tidak ada grid 24 slot sama sekali.) | L87: Tinggi
A88: 84 | B88: 3 | C88: MB-MON-04 / Weighbridge | D88: MB-MON-04 | E88: Weighbridge | F88: Mobile — Operasional Stasiun (MB-) | G88: Tanggal otomatis memakai tanggal perangkat, termasuk dini hari | H88: OPR-A | I88: ubah jam perangkat ke 01:00 waktu setempat | J88: 1. Ubah jam perangkat/emulator ke 01:00 waktu setempat, tanggal hari ini. 2. Login di mobile, Station List, lalu tekan tile Weighbridge (/stations/weighbridge/monitor), lalu tekan New Data. 3. Baca kolom Tanggal. 4. Bandingkan dengan tanggal pada jam perangkat. 5. Kembalikan jam perangkat ke keadaan semula. | K88: - Tanggal terisi dengan tanggal perangkat hari itu — bukan tanggal sebelumnya. - Pada 01:00, tanggalnya tetap tanggal kalender hari itu, bukan tanggal shift yang dimulai 07:00 kemarin. - Kolom Tanggal tidak dapat diubah manual (lihat LS-14 untuk keterangan yang harus menyertainya). | L88: Tinggi | M88: ini kasus yang mudah terlewat. Shift pabrik berjalan melewati tengah malam, jadi draft yang dibuat pukul 01:00 harus bertanggal hari itu.
A89: 85 | B89: 3 | C89: MB-MON-04 / Grading | D89: MB-MON-04 | E89: Grading | F89: Mobile — Operasional Stasiun (MB-) | G89: Tanggal otomatis memakai tanggal perangkat, termasuk dini hari | H89: OPR-A | I89: ubah jam perangkat ke 01:00 waktu setempat | J89: 1. Ubah jam perangkat/emulator ke 01:00 waktu setempat, tanggal hari ini. 2. Login di mobile, Station List, lalu tekan tile Grading (/stations/grading/monitor), lalu tekan New Data. 3. Baca kolom Tanggal. 4. Bandingkan dengan tanggal pada jam perangkat. 5. Kembalikan jam perangkat ke keadaan semula. | K89: - Tanggal terisi dengan tanggal perangkat hari itu — bukan tanggal sebelumnya. - Pada 01:00, tanggalnya tetap tanggal kalender hari itu, bukan tanggal shift yang dimulai 07:00 kemarin. - Kolom Tanggal tidak dapat diubah manual (lihat LS-14 untuk keterangan yang harus menyertainya). | L89: Tinggi | M89: ini kasus yang mudah terlewat. Shift pabrik berjalan melewati tengah malam, jadi draft yang dibuat pukul 01:00 harus bertanggal hari itu.
A90: 86 | B90: 3 | C90: MB-MON-04 / Cages Track | D90: MB-MON-04 | E90: Cages Track | F90: Mobile — Operasional Stasiun (MB-) | G90: Tanggal otomatis memakai tanggal perangkat, termasuk dini hari | H90: OPR-A | I90: ubah jam perangkat ke 01:00 waktu setempat | J90: 1. Ubah jam perangkat/emulator ke 01:00 waktu setempat, tanggal hari ini. 2. Login di mobile, Station List, lalu tekan tile Cages Track (/stations/cages-track/monitor), lalu tekan New Data. 3. Baca kolom Tanggal. 4. Bandingkan dengan tanggal pada jam perangkat. 5. Kembalikan jam perangkat ke keadaan semula. | K90: - Tanggal terisi dengan tanggal perangkat hari itu — bukan tanggal sebelumnya. - Pada 01:00, tanggalnya tetap tanggal kalender hari itu, bukan tanggal shift yang dimulai 07:00 kemarin. - Kolom Tanggal tidak dapat diubah manual (lihat LS-14 untuk keterangan yang harus menyertainya). | L90: Tinggi | M90: ini kasus yang mudah terlewat. Shift pabrik berjalan melewati tengah malam, jadi draft yang dibuat pukul 01:00 harus bertanggal hari itu.
A91: 87 | B91: 3 | C91: MB-MON-04 / Sterilizer | D91: MB-MON-04 | E91: Sterilizer | F91: Mobile — Operasional Stasiun (MB-) | G91: Tanggal otomatis memakai tanggal perangkat, termasuk dini hari | H91: OPR-A | I91: ubah jam perangkat ke 01:00 waktu setempat | J91: 1. Ubah jam perangkat/emulator ke 01:00 waktu setempat, tanggal hari ini. 2. Login di mobile, Station List, lalu tekan tile Sterilizer (/stations/sterilizer/monitor), lalu tekan New Data. 3. Baca kolom Tanggal. 4. Bandingkan dengan tanggal pada jam perangkat. 5. Kembalikan jam perangkat ke keadaan semula. | K91: - Tanggal terisi dengan tanggal perangkat hari itu — bukan tanggal sebelumnya. - Pada 01:00, tanggalnya tetap tanggal kalender hari itu, bukan tanggal shift yang dimulai 07:00 kemarin. - Kolom Tanggal tidak dapat diubah manual (lihat LS-14 untuk keterangan yang harus menyertainya). | L91: Tinggi | M91: ini kasus yang mudah terlewat. Shift pabrik berjalan melewati tengah malam, jadi draft yang dibuat pukul 01:00 harus bertanggal hari itu.
A92: 88 | B92: 3 | C92: MB-MON-04 / Threshing | D92: MB-MON-04 | E92: Threshing | F92: Mobile — Operasional Stasiun (MB-) | G92: Tanggal otomatis memakai tanggal perangkat, termasuk dini hari | H92: OPR-A | I92: ubah jam perangkat ke 01:00 waktu setempat | J92: 1. Ubah jam perangkat/emulator ke 01:00 waktu setempat, tanggal hari ini. 2. Login di mobile, Station List, lalu tekan tile Threshing (/stations/threshing/monitor), lalu tekan New Data. 3. Baca kolom Tanggal. 4. Bandingkan dengan tanggal pada jam perangkat. 5. Kembalikan jam perangkat ke keadaan semula. | K92: - Tanggal terisi dengan tanggal perangkat hari itu — bukan tanggal sebelumnya. - Pada 01:00, tanggalnya tetap tanggal kalender hari itu, bukan tanggal shift yang dimulai 07:00 kemarin. - Kolom Tanggal tidak dapat diubah manual (lihat LS-14 untuk keterangan yang harus menyertainya). | L92: Tinggi | M92: ini kasus yang mudah terlewat. Shift pabrik berjalan melewati tengah malam, jadi draft yang dibuat pukul 01:00 harus bertanggal hari itu.
A93: 89 | B93: 3 | C93: MB-MON-04 / Pressing | D93: MB-MON-04 | E93: Pressing | F93: Mobile — Operasional Stasiun (MB-) | G93: Tanggal otomatis memakai tanggal perangkat, termasuk dini hari | H93: OPR-A | I93: ubah jam perangkat ke 01:00 waktu setempat | J93: 1. Ubah jam perangkat/emulator ke 01:00 waktu setempat, tanggal hari ini. 2. Login di mobile, Station List, lalu tekan tile Pressing (/stations/pressing/monitor), lalu tekan New Data. 3. Baca kolom Tanggal. 4. Bandingkan dengan tanggal pada jam perangkat. 5. Kembalikan jam perangkat ke keadaan semula. | K93: - Tanggal terisi dengan tanggal perangkat hari itu — bukan tanggal sebelumnya. - Pada 01:00, tanggalnya tetap tanggal kalender hari itu, bukan tanggal shift yang dimulai 07:00 kemarin. - Kolom Tanggal tidak dapat diubah manual (lihat LS-14 untuk keterangan yang harus menyertainya). | L93: Tinggi | M93: ini kasus yang mudah terlewat. Shift pabrik berjalan melewati tengah malam, jadi draft yang dibuat pukul 01:00 harus bertanggal hari itu.
A94: 90 | B94: 3 | C94: MB-MON-04 / Clarification | D94: MB-MON-04 | E94: Clarification | F94: Mobile — Operasional Stasiun (MB-) | G94: Tanggal otomatis memakai tanggal perangkat, termasuk dini hari | H94: OPR-A | I94: ubah jam perangkat ke 01:00 waktu setempat | J94: 1. Ubah jam perangkat/emulator ke 01:00 waktu setempat, tanggal hari ini. 2. Login di mobile, Station List, lalu tekan tile Clarification (/stations/clarification/monitor), lalu tekan New Data. 3. Baca kolom Tanggal. 4. Bandingkan dengan tanggal pada jam perangkat. 5. Kembalikan jam perangkat ke keadaan semula. | K94: - Tanggal terisi dengan tanggal perangkat hari itu — bukan tanggal sebelumnya. - Pada 01:00, tanggalnya tetap tanggal kalender hari itu, bukan tanggal shift yang dimulai 07:00 kemarin. - Kolom Tanggal tidak dapat diubah manual (lihat LS-14 untuk keterangan yang harus menyertainya). | L94: Tinggi | M94: ini kasus yang mudah terlewat. Shift pabrik berjalan melewati tengah malam, jadi draft yang dibuat pukul 01:00 harus bertanggal hari itu.
A95: 91 | B95: 3 | C95: MB-MON-04 / Kernel Plant | D95: MB-MON-04 | E95: Kernel Plant | F95: Mobile — Operasional Stasiun (MB-) | G95: Tanggal otomatis memakai tanggal perangkat, termasuk dini hari | H95: OPR-A | I95: ubah jam perangkat ke 01:00 waktu setempat | J95: 1. Ubah jam perangkat/emulator ke 01:00 waktu setempat, tanggal hari ini. 2. Login di mobile, Station List, lalu tekan tile Kernel Plant (/stations/kernel-plant/monitor), lalu tekan New Data. 3. Baca kolom Tanggal. 4. Bandingkan dengan tanggal pada jam perangkat. 5. Kembalikan jam perangkat ke keadaan semula. | K95: - Tanggal terisi dengan tanggal perangkat hari itu — bukan tanggal sebelumnya. - Pada 01:00, tanggalnya tetap tanggal kalender hari itu, bukan tanggal shift yang dimulai 07:00 kemarin. - Kolom Tanggal tidak dapat diubah manual (lihat LS-14 untuk keterangan yang harus menyertainya). | L95: Tinggi | M95: ini kasus yang mudah terlewat. Shift pabrik berjalan melewati tengah malam, jadi draft yang dibuat pukul 01:00 harus bertanggal hari itu.
...

Sheet Rekap
A1: Rekap — terisi otomatis
A2: Angka di sini dihitung dari sheet Kasus Uji. Tidak perlu diisi tangan.
A4: Bagian | B4: Awalan ID | C4: Kasus unik | D4: Jml jalan | E4: Lulus | F4: Gagal | G4: Tidak diuji | H4: Terhalang | I4: Belum diisi
A5: Aturan lintas-sistem | B5: LS- | C5: 16 | D5: 16 | E5: =COUNTIFS('Kasus Uji'!$D$5:$D$1386,"LS-*",'Kasus Uji'!$P$5:$P$1386,"Lulus") | F5: =COUNTIFS('Kasus Uji'!$D$5:$D$1386,"LS-*",'Kasus Uji'!$P$5:$P$1386,"Gagal") | G5: =COUNTIFS('Kasus Uji'!$D$5:$D$1386,"LS-*",'Kasus Uji'!$P$5:$P$1386,"Tidak diuji") | H5: =COUNTIFS('Kasus Uji'!$D$5:$D$1386,"LS-*",'Kasus Uji'!$P$5:$P$1386,"Terhalang") | I5: =D5-E5-F5-G5-H5
A6: Autentikasi & Akun | B6: AU- | C6: 9 | D6: 9 | E6: =COUNTIFS('Kasus Uji'!$D$5:$D$1386,"AU-*",'Kasus Uji'!$P$5:$P$1386,"Lulus") | F6: =COUNTIFS('Kasus Uji'!$D$5:$D$1386,"AU-*",'Kasus Uji'!$P$5:$P$1386,"Gagal") | G6: =COUNTIFS('Kasus Uji'!$D$5:$D$1386,"AU-*",'Kasus Uji'!$P$5:$P$1386,"Tidak diuji") | H6: =COUNTIFS('Kasus Uji'!$D$5:$D$1386,"AU-*",'Kasus Uji'!$P$5:$P$1386,"Terhalang") | I6: =D6-E6-F6-G6-H6
A7: Mobile — Operasional Stasiun | B7: MB- | C7: 39 | D7: 474 | E7: =COUNTIFS('Kasus Uji'!$D$5:$D$1386,"MB-*",'Kasus Uji'!$P$5:$P$1386,"Lulus") | F7: =COUNTIFS('Kasus Uji'!$D$5:$D$1386,"MB-*",'Kasus Uji'!$P$5:$P$1386,"Gagal") | G7: =COUNTIFS('Kasus Uji'!$D$5:$D$1386,"MB-*",'Kasus Uji'!$P$5:$P$1386,"Tidak diuji") | H7: =COUNTIFS('Kasus Uji'!$D$5:$D$1386,"MB-*",'Kasus Uji'!$P$5:$P$1386,"Terhalang") | I7: =D7-E7-F7-G7-H7
A8: Web — Data Stasiun | B8: WB- | C8: 25 | D8: 429 | E8: =COUNTIFS('Kasus Uji'!$D$5:$D$1386,"WB-*",'Kasus Uji'!$P$5:$P$1386,"Lulus") | F8: =COUNTIFS('Kasus Uji'!$D$5:$D$1386,"WB-*",'Kasus Uji'!$P$5:$P$1386,"Gagal") | G8: =COUNTIFS('Kasus Uji'!$D$5:$D$1386,"WB-*",'Kasus Uji'!$P$5:$P$1386,"Tidak diuji") | H8: =COUNTIFS('Kasus Uji'!$D$5:$D$1386,"WB-*",'Kasus Uji'!$P$5:$P$1386,"Terhalang") | I8: =D8-E8-F8-G8-H8
A9: Laporan Periode Stasiun | B9: LP- | C9: 31 | D9: 341 | E9: =COUNTIFS('Kasus Uji'!$D$5:$D$1386,"LP-*",'Kasus Uji'!$P$5:$P$1386,"Lulus") | F9: =COUNTIFS('Kasus Uji'!$D$5:$D$1386,"LP-*",'Kasus Uji'!$P$5:$P$1386,"Gagal") | G9: =COUNTIFS('Kasus Uji'!$D$5:$D$1386,"LP-*",'Kasus Uji'!$P$5:$P$1386,"Tidak diuji") | H9: =COUNTIFS('Kasus Uji'!$D$5:$D$1386,"LP-*",'Kasus Uji'!$P$5:$P$1386,"Terhalang") | I9: =D9-E9-F9-G9-H9
A10: Dashboard & Laporan lain | B10: DS- | C10: 12 | D10: 12 | E10: =COUNTIFS('Kasus Uji'!$D$5:$D$1386,"DS-*",'Kasus Uji'!$P$5:$P$1386,"Lulus") | F10: =COUNTIFS('Kasus Uji'!$D$5:$D$1386,"DS-*",'Kasus Uji'!$P$5:$P$1386,"Gagal") | G10: =COUNTIFS('Kasus Uji'!$D$5:$D$1386,"DS-*",'Kasus Uji'!$P$5:$P$1386,"Tidak diuji") | H10: =COUNTIFS('Kasus Uji'!$D$5:$D$1386,"DS-*",'Kasus Uji'!$P$5:$P$1386,"Terhalang") | I10: =D10-E10-F10-G10-H10
A11: Master Data | B11: MD- | C11: 28 | D11: 91 | E11: =COUNTIFS('Kasus Uji'!$D$5:$D$1386,"MD-*",'Kasus Uji'!$P$5:$P$1386,"Lulus") | F11: =COUNTIFS('Kasus Uji'!$D$5:$D$1386,"MD-*",'Kasus Uji'!$P$5:$P$1386,"Gagal") | G11: =COUNTIFS('Kasus Uji'!$D$5:$D$1386,"MD-*",'Kasus Uji'!$P$5:$P$1386,"Tidak diuji") | H11: =COUNTIFS('Kasus Uji'!$D$5:$D$1386,"MD-*",'Kasus Uji'!$P$5:$P$1386,"Terhalang") | I11: =D11-E11-F11-G11-H11
A12: User & Role, Pengaturan Mill | B12: AD- | C12: 10 | D12: 10 | E12: =COUNTIFS('Kasus Uji'!$D$5:$D$1386,"AD-*",'Kasus Uji'!$P$5:$P$1386,"Lulus") | F12: =COUNTIFS('Kasus Uji'!$D$5:$D$1386,"AD-*",'Kasus Uji'!$P$5:$P$1386,"Gagal") | G12: =COUNTIFS('Kasus Uji'!$D$5:$D$1386,"AD-*",'Kasus Uji'!$P$5:$P$1386,"Tidak diuji") | H12: =COUNTIFS('Kasus Uji'!$D$5:$D$1386,"AD-*",'Kasus Uji'!$P$5:$P$1386,"Terhalang") | I12: =D12-E12-F12-G12-H12
A13: TOTAL | C13: =SUM(C5:C12) | D13: =SUM(D5:D12) | E13: =SUM(E5:E12) | F13: =SUM(F5:F12) | G13: =SUM(G5:G12) | H13: =SUM(H5:H12) | I13: =SUM(I5:I12)
A15: Kasus Prioritas Tinggi yang belum diisi | D15: =COUNTIFS('Kasus Uji'!$L$5:$L$1386,"Tinggi",'Kasus Uji'!$P$5:$P$1386,"")
A16: Baris Gagal yang belum punya No. Bug | D16: =COUNTIFS('Kasus Uji'!$P$5:$P$1386,"Gagal",'Kasus Uji'!$Q$5:$Q$1386,"")
A18: Kemajuan per Tingkat
A19: Tingkat | B19: Apa isinya | C19: Jalan | D19: Lulus | E19: Gagal | F19: Tidak diuji | G19: Terhalang | H19: Belum diisi
A20: 1 | B20: ALUR — setiap kasus sekali, pada stasiun wakil. Membuktikan setiap alur bekerja. | C20: 170 | D20: =COUNTIFS('Kasus Uji'!$B$5:$B$1386,1,'Kasus Uji'!$P$5:$P$1386,"Lulus") | E20: =COUNTIFS('Kasus Uji'!$B$5:$B$1386,1,'Kasus Uji'!$P$5:$P$1386,"Gagal") | F20: =COUNTIFS('Kasus Uji'!$B$5:$B$1386,1,'Kasus Uji'!$P$5:$P$1386,"Tidak diuji") | G20: =COUNTIFS('Kasus Uji'!$B$5:$B$1386,1,'Kasus Uji'!$P$5:$P$1386,"Terhalang") | H20: =C20-D20-E20-F20-G20
A21: 2 | B21: KABEL — 5 kasus pada 17 stasiun sisanya. Menangkap stasiun yang salah dikabel. | C21: 88 | D21: =COUNTIFS('Kasus Uji'!$B$5:$B$1386,2,'Kasus Uji'!$P$5:$P$1386,"Lulus") | E21: =COUNTIFS('Kasus Uji'!$B$5:$B$1386,2,'Kasus Uji'!$P$5:$P$1386,"Gagal") | F21: =COUNTIFS('Kasus Uji'!$B$5:$B$1386,2,'Kasus Uji'!$P$5:$P$1386,"Tidak diuji") | G21: =COUNTIFS('Kasus Uji'!$B$5:$B$1386,2,'Kasus Uji'!$P$5:$P$1386,"Terhalang") | H21: =C21-D21-E21-F21-G21
A22: 3 | B22: SISA — pengulangan penuh. Untuk putaran rilis atau saat satu stasiun berubah. | C22: 1124 | D22: =COUNTIFS('Kasus Uji'!$B$5:$B$1386,3,'Kasus Uji'!$P$5:$P$1386,"Lulus") | E22: =COUNTIFS('Kasus Uji'!$B$5:$B$1386,3,'Kasus Uji'!$P$5:$P$1386,"Gagal") | F22: =COUNTIFS('Kasus Uji'!$B$5:$B$1386,3,'Kasus Uji'!$P$5:$P$1386,"Tidak diuji") | G22: =COUNTIFS('Kasus Uji'!$B$5:$B$1386,3,'Kasus Uji'!$P$5:$P$1386,"Terhalang") | H22: =C22-D22-E22-F22-G22
A23: Tingkat 1+2 | B23: Cakupan yang masuk akal untuk pengujian manual satu putaran. | C23: 258 | D23: =SUM(D20:D21) | E23: =SUM(E20:E21) | F23: =SUM(F20:F21) | G23: =SUM(G20:G21) | H23: =SUM(H20:H21)
A25: Tingkat 1 melewati ke-170 kasus unik tepat SEKALI — jadi menyelesaikannya berarti setiap alur sistem sudah pernah dijalankan. Yang belum terbukti sesudahnya adalah 17 stasiun lain, dan itulah Tingkat 2.

Sheet Lingkungan & Akun
A1: Lingkungan & akun uji
A2: Seluruh kasus mengandaikan isi sheet ini sudah disiapkan. Tanpa 6 akun di bawah, kasus isolasi mill tidak dapat diuji sama sekali.
A4: Yang harus siap sebelum menguji
A5: Hal | B5: Keterangan
A6: Aplikasi Web | B6: Dibuka di browser desktop. Lebar layar minimal 1280px untuk layar tabel.
A7: Aplikasi Mobile | B7: Dibuka di perangkat atau emulator. Lebar acuan 390px.
A8: Koneksi | B8: Perlu bisa DIMATIKAN untuk menguji mode offline mobile.
A9: Data master | B9: Minimal: 1 Corporate, 1 Company, 2 Mill, masing-masing 2 Production Line, dan stasiun aktif untuk ke-18 jenis.
A10: Periode Pelaporan | B10: Minimal satu periode yang mencakup hari ini, dengan stasiun berstatus Terbuka.
A12: Akun uji — minimal 6
A13: Kode akun | B13: Peran | C13: Mill | D13: Dipakai untuk
A14: OPR-A | B14: Station Operator | C14: Mill A | D14: Alur input mobile
A15: SPV-A | B15: Supervisor | C15: Mill A | D15: Input + verifikasi "Checked"
A16: MGR-A | B16: Mill Management | C16: Mill A | D16: Verifikasi "Acknowledged", Pengaturan Mill
A17: SPV-B | B17: Supervisor | C17: Mill B | D17: Menguji data Mill A tidak terlihat
A18: ADM | B18: Admin | C18: — (tidak terikat mill) | D18: Master data, Periode Pelaporan
A19: NOMILL | B19: Supervisor | C19: tanpa mill | D19: Menguji sistem menolak dengan jelas
A20: Akun NOMILL sengaja dibuat cacat. Beberapa kasus menguji bahwa sistem MENOLAK DENGAN PESAN YANG MENYEBUT SEBABNYA alih-alih menampilkan halaman kosong — halaman kosong terbaca sebagai "tidak ada data", padahal yang benar adalah "akun Anda belum diatur".
A22: Matriks peran — acuan seluruh kasus LS-01
A23: Kemampuan | B23: Operator | C23: Supervisor | D23: Mill Management | E23: Admin | F23: Catatan
A24: Login Mobile | B24: ✓ | C24: ✓ | D24: ✓ | E24: ✓ | F24: Admin bukan alur yang dirancang
A25: Login Web | B25: v terbatas | C25: ✓ | D25: ✓ | E25: ✓ | F25: Operator: hanya 3 layar, lihat baris terbawah
A26: Input data stasiun (Mobile) | B26: ✓ | C26: ✓ | D26: ✓ | E26: —
A27: Input data stasiun (Web) | B27: — | C27: ✓ | D27: ✓ | E27: ✓
A28: Isi Checked By | B28: — | C28: ✓ | D28: — | E28: ✓
A29: Isi Acknowledged By | B29: — | C29: — | D29: ✓ | E29: ✓
A30: Lihat Data Browser / Detail (Web) | B30: — | C30: ✓ | D30: ✓ | E30: ✓
A31: Lihat "Data Saya" (Web) | B31: ✓ | C31: ✓ | D31: — | E31: —
A32: Laporan periode stasiun (Web) | B32: — | C32: ✓ | D32: ✓ | E32: ✓
A33: Laporan periode stasiun (Mobile) | B33: ✓ | C33: ✓ | D33: ✓ | E33: ✓
A34: Dashboard (Web) | B34: — | C34: ✓ | D34: ✓ | E34: ✓
A35: Laporan Manajemen | B35: — | C35: — | D35: ✓ | E35: ✓
A36: Master data (Corporate…Mesin) | B36: — | C36: — | D36: — | E36: ✓
A37: Periode Pelaporan: tambah/ubah/hapus | B37: — | C37: — | D37: — | E37: ✓
A38: Tutup / Buka Periode | B38: — | C38: — | D38: — | E38: ✓ | F38: HANYA Admin
A39: Pengaturan Mill | B39: — | C39: — | D39: v mill sendiri | E39: v semua mill
A40: Kelola User & Role | B40: — | C40: — | D40: — | E40: ✓
A41: Pemilih Mill pada laporan | B41: — | C41: — | D41: — | E41: ✓ | F41: HANYA Admin
A42: Akses web Operator dibatasi pada: Beranda Operator, Ganti Password, dan Data Saya. Seluruh alamat lain harus menjawab halaman 403 (Akses Ditolak) — bukan halaman kosong, bukan diarahkan diam-diam ke beranda.

Sheet Matriks Stasiun
A1: Matriks 18 stasiun
A2: "Kolom wajib" = kolom identitas unit yang harus diisi sebelum Simpan. "Jml kolom bacaan" = banyaknya kolom pengukuran per baris slot waktu, dipakai pada MB-FORM-05. ± berarti jumlahnya berbeda per stasiun dan dibaca dari layar saat menguji.
A4: No | B4: Stasiun | C4: Kolom wajib | D4: Jml kolom bacaan | E4: Pola | F4: Laporan periode | G4: Keanehan yang perlu diperhatikan
A5: 1 | B5: Weighbridge | C5: No. Kartu / Kendaraan | D5: per-transaksi | E5: Per-transaksi | F5: Ada (web+mobile) | G5: BUKAN pola 24 slot — satu record per transaksi timbang, ada arus Masuk & Keluar
A6: 2 | B6: Grading | C6: Parameter grading | D6: per-muatan | E6: Per-transaksi | F6: Ada (web+mobile) | G6: Satu record per muatan, ada beberapa baris parameter
A7: 3 | B7: Cages Track | C7: ID Cage | D7: ± | E7: 24 slot | F7: Ada (web+mobile)
A8: 4 | B8: Sterilizer | C8: ID Sterilizer | D8: ± | E8: 24 slot | F8: Ada (web+mobile) | G8: Ada checkbox "Checked by SPV" per baris — Operator tidak boleh bisa mengisinya
A9: 5 | B9: Threshing | C9: ID Thresher | D9: 5 | E9: 24 slot | F9: Ada (web+mobile) | G9: Punya master target
A10: 6 | B10: Pressing | C10: ID Presser | D10: 5 | E10: 24 slot | F10: Ada (web+mobile) | G10: Punya master target
A11: 7 | B11: Clarification | C11: ID unit | D11: ± | E11: 24 slot | F11: Ada (web+mobile)
A12: 8 | B12: Kernel Plant | C12: ID unit kernel plant | D12: 7 | E12: 24 slot | F12: Ada (web+mobile) | G12: Punya master target. Dua pasang kolom berbagi satu standar (2 ripple mill, 2 kernel silo)
A13: 9 | B13: Boiler Room | C13: ID boiler | D13: ± | E13: 24 slot | F13: Ada (web+mobile)
A14: 10 | B14: Effluent Plant | C14: ID unit | D14: 14 | E14: 24 slot | F14: BELUM dibangun | G14: PALING BANYAK KOLOM. Ada 3 kolom status pilihan (on/off/fault, run/stop) dan 2 kolom teks bebas
A15: 11 | B15: Depricarping | C15: ID Presser | D15: 7 | E15: 24 slot | F15: Ada (web+mobile) | G15: Punya master target. Ada kolom Downtime (menit) berupa angka + kolom Temuan
A16: 12 | B16: Engine Room | C16: ID unit | D16: ± | E16: 24 slot | F16: Belum
A17: 13 | B17: Process Water | C17: ID unit | D17: ± | E17: 24 slot | F17: Belum | G17: Ada kolom shift & petugas
A18: 14 | B18: Storage Tank | C18: ID tangki | D18: ± | E18: 24 slot | F18: Ada (web+mobile)
A19: 15 | B19: Solid Waste Disposal | C19: ID unit | D19: ± | E19: 24 slot | F19: Belum
A20: 16 | B20: Kernel Dispatch | C20: No. Kartu / Kendaraan | D20: per-transaksi | E20: Per-transaksi | F20: Belum | G20: Pola per-transaksi, ada kolom status pilihan
A21: 17 | B21: CPO Dispatch | C21: No. Kartu / Kendaraan | D21: per-transaksi | E21: Per-transaksi | F21: Belum | G21: Pola per-transaksi
A22: 18 | B22: Process Quality Control | C22: ID unit | D22: ± | E22: 24 slot | F22: Belum
A24: Weighbridge, Grading, Kernel Dispatch, dan CPO Dispatch tidak memakai 24 slot waktu. Untuk keempat stasiun ini MB-FORM-03 dan MB-FORM-04 (aturan urutan slot) digantikan MB-FORM-11. Di sheet Kasus Uji baris-baris itu memang tidak ada — yang terdaftar hanya jalan yang dapat dikerjakan.
A25: 11 stasiun sudah punya laporan periode, jadi LP- dijalankan 11× untuk web dan 11× untuk mobile. Tile stasiun yang laporannya belum ada harus KELABU DAN TIDAK DAPAT DITEKAN — diuji oleh DS-04 dan DS-07, bukan hilang dari layar.

Sheet Catatan & Batasan
A1: Catatan & Batasan — baca sebelum melapor
A2: Dua daftar. Yang pertama sudah diketahui tim dan bukan temuan baru. Yang kedua TERLIHAT seperti bug tetapi perilakunya benar — keenamnya akan dilaporkan oleh QA yang belum membaca halaman ini.
A4: Batasan yang sudah diketahui
A5: Hal-hal di bawah sudah diketahui dan bukan temuan baru. Kalau penguji menemukannya, cukup rujuk nomornya alih-alih membuat laporan bug baru.
A6: No | B6: Hal | C6: Keterangan
A7: B-1 | B7: Laporan periode belum tersedia untuk 7 stasiun | C7: Engine Room, Process Water, Solid Waste Disposal, Kernel Dispatch, CPO Dispatch, Process Quality Control, dan Effluent Plant belum punya layar laporan periode. Tile-nya tetap TAMPIL di layar Laporan Stasiun dalam keadaan kelabu dan tidak dapat ditekan — supaya pembaca tahu stasiun itu ada. Input data untuk ketujuh stasiun tersebut SUDAH tersedia, baik di web maupun mobile.
A8: B-2 | B8: Layar "Data Saya" belum tersedia | C8: Daftar record yang dibuat pengguna itu sendiri belum ada. Akibatnya akses web untuk peran Station Operator terbatas pada dua layar: Beranda Operator dan Ganti Password. Operator tetap dapat menginput lewat aplikasi mobile seperti biasa.
A9: B-3 | B9: Dashboard adalah tampilan contoh, bukan laporan mill | C9: Halaman Dashboard menampilkan contoh laporan harian dengan angka tetap — tanpa filter tanggal dan tanpa pemilih mill, dan tidak membaca data stasiun. Ia MENYATAKAN dirinya contoh lewat judul "CPO Mill Demo" dan penanda "Data dummy". Kasus DS-01 justru memeriksa bahwa penanda itu ada; penanda yang hilang adalah temuan prioritas tinggi. Angka operasional yang sebenarnya ada di Laporan Periode per stasiun.
A10: B-4 | B10: Satuan suhu ditulis "C", bukan "°C" | C10: Pada laporan Kernel Plant, web maupun mobile. Disengaja: satuannya mengikuti data master apa adanya, dan mengubahnya di tampilan akan membuat web dan mobile berselisih.
A11: B-5 | B11: Laporan Depricarping (Mobile): tiga angka pada blok downtime tampil tanpa gaya | C11: Angkanya benar; hanya tampilannya yang belum rapi. Kosmetik, sudah tercatat.
A14: Hal yang TERLIHAT seperti bug tetapi BUKAN
A15: Kasus | B15: Kelihatan salah | C15: Sebenarnya
A16: LS-16 | B16: Laporan tidak menandai nilai yang jelas di luar batas | C16: DISENGAJA. Kolom targetnya teks bebas yang bentuknya tidak dibatasi, dan satu sel bisa memuat dua angka dengan satuan berbeda. Ada kalimat di layar yang menjelaskannya.
A17: MB-FORM-04 | B17: Slot waktu 01:00 dianggap SESUDAH 23:00 | C17: BENAR. Shift dimulai 07:00, jadi urutannya 07:00 → 23:00 → 00:00 → 06:00.
A18: DS-02 | B18: Dashboard menampilkan angka yang sama untuk semua peran dan semua mill | C18: BENAR. Halaman itu tampilan contoh dengan angka tetap, dan menyatakannya lewat penanda "Data dummy". Jangan jalankan uji isolasi mill di sana — ia tidak membaca mill sama sekali.
A19: DS-10 | B19: Satu stasiun menunjukkan "belum ada input hari ini" DAN "input terakhir 3 menit lalu" | C19: BENAR. Dua jendela waktu yang berbeda: "hari ini" dibatasi tanggal, "input terakhir" tidak. Keterangan di halaman menjelaskannya.
A20: LP-W-05 | B20: Persen cakupan 0,0% di satu periode dan tanda pisah di periode lain, keduanya "tanpa data" | C20: BENAR, DAN KEDUANYA BERBEDA. 0,0% = penyebutnya ada, nol yang terisi. Tanda pisah = penyebutnya tidak terbentuk.
A21: LP-W-03 | B21: Jumlah slot terisi pada cakupan LEBIH BESAR daripada penyebut parameter mana pun | C21: BENAR. Slot yang hanya mengisi kolom temuan terhitung terisi tanpa menambah penyebut parameter.
A22: LS-08 | B22: Production Line tunggal tetap harus dipilih manual | C22: DISENGAJA. Memilihnya otomatis membuat pembaca mengira ia melihat seluruh mill.
